<sdf version='1.7'>
  <model name='gem_e4'>
    <link name='base_footprint'>
      <inertial>
        <pose>-0.012043 0.001203 0.747456 0 -0 0</pose>
        <mass>1952.83</mass>
        <inertia>
          <ixx>550.184</ixx>
          <ixy>-0.508338</ixy>
          <ixz>-13.2054</ixz>
          <iyy>1806.58</iyy>
          <iyz>0.0934486</iyz>
          <izz>1704.42</izz>
        </inertia>
      </inertial>
      <collision name='base_footprint_fixed_joint_lump__base_link_collision'>
        <pose>0 0 0.268 0 -0 0</pose>
        <geometry>
          <mesh>
            <scale>1 1 1</scale>
            <uri>model://gem_description/meshes/e4/base_link.STL</uri>
          </mesh>
        </geometry>
        <surface>
          <contact>
            <ode/>
          </contact>
          <friction>
            <ode/>
          </friction>
        </surface>
      </collision>
      <collision name='base_footprint_fixed_joint_lump__GPS_link_collision_1'>
        <pose>-0.246 0 0.318 0 -0 0</pose>
        <geometry>
          <box>
            <size>0.1 0.1 0.1</size>
          </box>
        </geometry>
        <surface>
          <contact>
            <ode/>
          </contact>
          <friction>
            <ode/>
          </friction>
        </surface>
      </collision>
      <collision name='base_footprint_fixed_joint_lump__IMU_link_collision_2'>
        <pose>-0.246 0 0.318 0 0 -1.5708</pose>
        <geometry>
          <box>
            <size>0.1 0.1 0.1</size>
          </box>
        </geometry>
        <surface>
          <contact>
            <ode/>
          </contact>
          <friction>
            <ode/>
          </friction>
        </surface>
      </collision>
      <collision name='base_footprint_fixed_joint_lump__front_camera_link_collision_3'>
        <pose>0.535 0 1.951 0 1.5708 0</pose>
        <geometry>
          <mesh>
            <scale>1 1 1</scale>
            <uri>model://gem_description/meshes/e4/front_camera_link.STL</uri>
          </mesh>
        </geometry>
        <surface>
          <contact>
            <ode/>
          </contact>
          <friction>
            <ode/>
          </friction>
        </surface>
      </collision>
      <collision name='base_footprint_fixed_joint_lump__front_single_camera_link_collision_4'>
        <pose>0.535 0 1.951 0 0.0008 0</pose>
        <geometry>
          <box>
            <size>0.05 0.05 0.05</size>
          </box>
        </geometry>
        <surface>
          <contact>
            <ode/>
          </contact>
          <friction>
            <ode/>
          </friction>
        </surface>
      </collision>
      <collision name='base_footprint_fixed_joint_lump__front_lidar_link_collision_5'>
        <pose>0.38206 0 1.978 0 -0 0</pose>
        <geometry>
          <mesh>
            <scale>1 1 1</scale>
            <uri>model://gem_description/meshes/e4/front_lidar_link.STL</uri>
          </mesh>
        </geometry>
        <surface>
          <contact>
            <ode/>
          </contact>
          <friction>
            <ode/>
          </friction>
        </surface>
      </collision>
      <collision name='base_footprint_fixed_joint_lump__front_rack_link_collision_6'>
        <pose>1.7594 0 0.118 1.5708 -0 1.5708</pose>
        <geometry>
          <mesh>
            <scale>1 1 1</scale>
            <uri>model://gem_description/meshes/e4/front_rack_link.STL</uri>
          </mesh>
        </geometry>
        <surface>
          <contact>
            <ode/>
          </contact>
          <friction>
            <ode/>
          </friction>
        </surface>
      </collision>
      <collision name='base_footprint_fixed_joint_lump__front_sonar_link_collision_7'>
        <pose>1.8244 0 0.498 -4e-06 -0 4e-06</pose>
        <geometry>
          <box>
            <size>0.05 0.2 0.1</size>
          </box>
        </geometry>
        <surface>
          <contact>
            <ode/>
          </contact>
          <friction>
            <ode/>
          </friction>
        </surface>
      </collision>
      <collision name='base_footprint_fixed_joint_lump__front_radar_link_collision_8'>
        <pose>1.835 0 0.618 0 -0 0</pose>
        <geometry>
          <mesh>
            <scale>1 1 1</scale>
            <uri>model://gem_description/meshes/e4/front_radar_link.STL</uri>
          </mesh>
        </geometry>
        <surface>
          <contact>
            <ode/>
          </contact>
          <friction>
            <ode/>
          </friction>
        </surface>
      </collision>
      <collision name='base_footprint_fixed_joint_lump__gps_antenna_aux_link_collision_9'>
        <pose>-0.01144 -0.6525 1.968 0 -0 0</pose>
        <geometry>
          <mesh>
            <scale>1 1 1</scale>
            <uri>model://gem_description/meshes/e4/gps_antenna_aux_link.STL</uri>
          </mesh>
        </geometry>
        <surface>
          <contact>
            <ode/>
          </contact>
          <friction>
            <ode/>
          </friction>
        </surface>
      </collision>
      <collision name='base_footprint_fixed_joint_lump__gps_antenna_main_link_collision_10'>
        <pose>-0.01144 0.6525 1.968 0 -0 0</pose>
        <geometry>
          <mesh>
            <scale>1 1 1</scale>
            <uri>model://gem_description/meshes/e4/gps_antenna_main_link.STL</uri>
          </mesh>
        </geometry>
        <surface>
          <contact>
            <ode/>
          </contact>
          <friction>
            <ode/>
          </friction>
        </surface>
      </collision>
      <collision name='base_footprint_fixed_joint_lump__headlight_fl_link_collision_11'>
        <pose>1.1677 0.5 1.033 0 -0 0</pose>
        <geometry>
          <mesh>
            <scale>1 1 1</scale>
            <uri>model://gem_description/meshes/e4/headlight_fl_link.STL</uri>
          </mesh>
        </geometry>
        <surface>
          <contact>
            <ode/>
          </contact>
          <friction>
            <ode/>
          </friction>
        </surface>
      </collision>
      <collision name='base_footprint_fixed_joint_lump__headlight_fr_link_collision_12'>
        <pose>1.1677 -0.5 1.033 0 -0 0</pose>
        <geometry>
          <mesh>
            <scale>1 1 1</scale>
            <uri>model://gem_description/meshes/e4/headlight_fr_link.STL</uri>
          </mesh>
        </geometry>
        <surface>
          <contact>
            <ode/>
          </contact>
          <friction>
            <ode/>
          </friction>
        </surface>
      </collision>
      <collision name='base_footprint_fixed_joint_lump__i_logo_fl_link_collision_13'>
        <pose>0.3966 0.6695 0.6803 0 -0 0</pose>
        <geometry>
          <mesh>
            <scale>1 1 1</scale>
            <uri>model://gem_description/meshes/e4/i_logo_link.STL</uri>
          </mesh>
        </geometry>
        <surface>
          <contact>
            <ode/>
          </contact>
          <friction>
            <ode/>
          </friction>
        </surface>
      </collision>
      <collision name='base_footprint_fixed_joint_lump__i_logo_fr_link_collision_14'>
        <pose>0.3966 -0.68 0.6803 0 -0 0</pose>
        <geometry>
          <mesh>
            <scale>1 1 1</scale>
            <uri>model://gem_description/meshes/e4/i_logo_link.STL</uri>
          </mesh>
        </geometry>
        <surface>
          <contact>
            <ode/>
          </contact>
          <friction>
            <ode/>
          </friction>
        </surface>
      </collision>
      <collision name='base_footprint_fixed_joint_lump__i_logo_rl_link_collision_15'>
        <pose>-0.42344 0.6695 0.6803 0 -0 0</pose>
        <geometry>
          <mesh>
            <scale>1 1 1</scale>
            <uri>model://gem_description/meshes/e4/i_logo_link.STL</uri>
          </mesh>
        </geometry>
        <surface>
          <contact>
            <ode/>
          </contact>
          <friction>
            <ode/>
          </friction>
        </surface>
      </collision>
      <collision name='base_footprint_fixed_joint_lump__i_logo_rr_link_collision_16'>
        <pose>-0.42344 -0.68 0.6803 0 -0 0</pose>
        <geometry>
          <mesh>
            <scale>1 1 1</scale>
            <uri>model://gem_description/meshes/e4/i_logo_link.STL</uri>
          </mesh>
        </geometry>
        <surface>
          <contact>
            <ode/>
          </contact>
          <friction>
            <ode/>
          </friction>
        </surface>
      </collision>
      <collision name='base_footprint_fixed_joint_lump__imu_link_collision_17'>
        <pose>-0.004439 0 0.45094 0 -0 0</pose>
        <geometry>
          <mesh>
            <scale>1 1 1</scale>
            <uri>model://gem_description/meshes/e4/imu_link.STL</uri>
          </mesh>
        </geometry>
        <surface>
          <contact>
            <ode/>
          </contact>
          <friction>
            <ode/>
          </friction>
        </surface>
      </collision>
      <collision name='base_footprint_fixed_joint_lump__lightbar_link_collision_18'>
        <pose>-1.07655 0 1.2129 -1.9138 -0 1.5708</pose>
        <geometry>
          <mesh>
            <scale>1 1 1</scale>
            <uri>model://gem_description/meshes/e4/lightbar_link.STL</uri>
          </mesh>
        </geometry>
        <surface>
          <contact>
            <ode/>
          </contact>
          <friction>
            <ode/>
          </friction>
        </surface>
      </collision>
      <collision name='base_footprint_fixed_joint_lump__rear_rack_link_collision_19'>
        <pose>-1.7372 0 0.168 1.5708 0 -1.5708</pose>
        <geometry>
          <mesh>
            <scale>1 1 1</scale>
            <uri>model://gem_description/meshes/e4/rear_rack_link.STL</uri>
          </mesh>
        </geometry>
        <surface>
          <contact>
            <ode/>
          </contact>
          <friction>
            <ode/>
          </friction>
        </surface>
      </collision>
      <collision name='base_footprint_fixed_joint_lump__rear_sonar_link_collision_20'>
        <pose>-1.8022 0 0.548 -4e-06 -0 3.14159</pose>
        <geometry>
          <box>
            <size>0.05 0.2 0.1</size>
          </box>
        </geometry>
        <surface>
          <contact>
            <ode/>
          </contact>
          <friction>
            <ode/>
          </friction>
        </surface>
      </collision>
      <collision name='base_footprint_fixed_joint_lump__rear_left_stop_light_link_collision_21'>
        <pose>-1.625 0.38 0.691 0 0 -3.14159</pose>
        <geometry>
          <mesh>
            <scale>1 1 1</scale>
            <uri>model://gem_description/meshes/e4/stoplight_rl_link.STL</uri>
          </mesh>
        </geometry>
        <surface>
          <contact>
            <ode/>
          </contact>
          <friction>
            <ode/>
          </friction>
        </surface>
      </collision>
      <collision name='base_footprint_fixed_joint_lump__rear_right_stop_light_link_collision_22'>
        <pose>-1.625 -0.38 0.691 0 0 -3.14159</pose>
        <geometry>
          <mesh>
            <scale>1 1 1</scale>
            <uri>model://gem_description/meshes/e4/stoplight_rr_link.STL</uri>
          </mesh>
        </geometry>
        <surface>
          <contact>
            <ode/>
          </contact>
          <friction>
            <ode/>
          </friction>
        </surface>
      </collision>
      <collision name='base_footprint_fixed_joint_lump__taillight_rl_link_collision_23'>
        <pose>-1.62 0.32 0.471 0 0 -3.14159</pose>
        <geometry>
          <mesh>
            <scale>1 1 1</scale>
            <uri>model://gem_description/meshes/e4/taillight_rl_link.STL</uri>
          </mesh>
        </geometry>
        <surface>
          <contact>
            <ode/>
          </contact>
          <friction>
            <ode/>
          </friction>
        </surface>
      </collision>
      <collision name='base_footprint_fixed_joint_lump__taillight_rr_link_collision_24'>
        <pose>-1.62 -0.32 0.471 0 0 -3.14159</pose>
        <geometry>
          <mesh>
            <scale>1 1 1</scale>
            <uri>model://gem_description/meshes/e4/taillight_rr_link.STL</uri>
          </mesh>
        </geometry>
        <surface>
          <contact>
            <ode/>
          </contact>
          <friction>
            <ode/>
          </friction>
        </surface>
      </collision>
      <collision name='base_footprint_fixed_joint_lump__top_lidar_link_collision_25'>
        <pose>-0.15144 0 2.348 0 -0 0</pose>
        <geometry>
          <mesh>
            <scale>1 1 1</scale>
            <uri>model://gem_description/meshes/e4/top_lidar_link.STL</uri>
          </mesh>
        </geometry>
        <surface>
          <contact>
            <ode/>
          </contact>
          <friction>
            <ode/>
          </friction>
        </surface>
      </collision>
      <collision name='base_footprint_fixed_joint_lump__top_rack_link_collision_26'>
        <pose>-0.17 0 1.928 1.5708 -0 0</pose>
        <geometry>
          <mesh>
            <scale>1 1 1</scale>
            <uri>model://gem_description/meshes/e4/top_rack_link.STL</uri>
          </mesh>
        </geometry>
        <surface>
          <contact>
            <ode/>
          </contact>
          <friction>
            <ode/>
          </friction>
        </surface>
      </collision>
      <collision name='base_footprint_fixed_joint_lump__base_collision_collision_27'>
        <pose>-0.15 -2e-06 2.3845 0 7e-06 3.14159</pose>
        <geometry>
          <cylinder>
            <length>0.073</length>
            <radius>0.04</radius>
          </cylinder>
        </geometry>
      </collision>
      <collision name='base_footprint_fixed_joint_lump__turnlight_fl_link_collision_28'>
        <pose>1.1731 0.345 1.033 0 -0 0</pose>
        <geometry>
          <mesh>
            <scale>1 1 1</scale>
            <uri>model://gem_description/meshes/e4/turnlight_fl_link.STL</uri>
          </mesh>
        </geometry>
        <surface>
          <contact>
            <ode/>
          </contact>
          <friction>
            <ode/>
          </friction>
        </surface>
      </collision>
      <collision name='base_footprint_fixed_joint_lump__turnlight_fr_link_collision_29'>
        <pose>1.1731 -0.345 1.033 0 -0 0</pose>
        <geometry>
          <mesh>
            <scale>1 1 1</scale>
            <uri>model://gem_description/meshes/e4/turnlight_fr_link.STL</uri>
          </mesh>
        </geometry>
        <surface>
          <contact>
            <ode/>
          </contact>
          <friction>
            <ode/>
          </friction>
        </surface>
      </collision>
      <visual name='base_footprint_fixed_joint_lump__base_link_visual'>
        <pose>0 0 0.268 0 -0 0</pose>
        <geometry>
          <mesh>
            <scale>1 1 1</scale>
            <uri>model://gem_description/meshes/e4/base_link.STL</uri>
          </mesh>
        </geometry>
        <material>
          <script>
            <name>Gazebo/Blue</name>
            <uri>file://media/materials/scripts/gazebo.material</uri>
          </script>
        </material>
      </visual>
      <visual name='base_footprint_fixed_joint_lump__GPS_link_visual_1'>
        <pose>-0.246 0 0.318 0 -0 0</pose>
        <geometry>
          <box>
            <size>0.1 0.1 0.1</size>
          </box>
        </geometry>
        <material>
          <script>
            <name>Gazebo/White</name>
            <uri>file://media/materials/scripts/gazebo.material</uri>
          </script>
        </material>
      </visual>
      <visual name='base_footprint_fixed_joint_lump__IMU_link_visual_2'>
        <pose>-0.246 0 0.318 0 0 -1.5708</pose>
        <geometry>
          <box>
            <size>0.1 0.1 0.1</size>
          </box>
        </geometry>
        <material>
          <script>
            <name>Gazebo/White</name>
            <uri>file://media/materials/scripts/gazebo.material</uri>
          </script>
        </material>
      </visual>
      <visual name='base_footprint_fixed_joint_lump__front_camera_link_visual_3'>
        <pose>0.535 0 1.951 0 1.5708 0</pose>
        <geometry>
          <mesh>
            <scale>1 1 1</scale>
            <uri>model://gem_description/meshes/e4/front_camera_link.STL</uri>
          </mesh>
        </geometry>
        <material>
          <script>
            <name>Gazebo/White</name>
            <uri>file://media/materials/scripts/gazebo.material</uri>
          </script>
        </material>
      </visual>
      <visual name='base_footprint_fixed_joint_lump__front_single_camera_link_visual_4'>
        <pose>0.535 0 1.951 0 0.0008 0</pose>
        <geometry>
          <box>
            <size>0.05 0.05 0.05</size>
          </box>
        </geometry>
        <material>
          <script>
            <name>Gazebo/White</name>
            <uri>file://media/materials/scripts/gazebo.material</uri>
          </script>
        </material>
      </visual>
      <visual name='base_footprint_fixed_joint_lump__front_left_corner_camera_link_visual_5'>
        <pose>0.5 0.6545 2.018 0 0.785 0.785</pose>
        <geometry>
          <box>
            <size>0.02 0.02 0.01</size>
          </box>
        </geometry>
        <material>
          <script>
            <name>Gazebo/Red</name>
            <uri>file://media/materials/scripts/gazebo.material</uri>
          </script>
        </material>
      </visual>
      <visual name='base_footprint_fixed_joint_lump__front_lidar_link_visual_6'>
        <pose>0.38206 0 1.978 0 -0 0</pose>
        <geometry>
          <mesh>
            <scale>1 1 1</scale>
            <uri>model://gem_description/meshes/e4/front_lidar_link.STL</uri>
          </mesh>
        </geometry>
        <material>
          <script>
            <name>Gazebo/White</name>
            <uri>file://media/materials/scripts/gazebo.material</uri>
          </script>
        </material>
      </visual>
      <visual name='base_footprint_fixed_joint_lump__front_rack_link_visual_7'>
        <pose>1.7594 0 0.118 1.5708 -0 1.5708</pose>
        <geometry>
          <mesh>
            <scale>1 1 1</scale>
            <uri>model://gem_description/meshes/e4/front_rack_link.STL</uri>
          </mesh>
        </geometry>
        <material>
          <script>
            <name>Gazebo/Black</name>
            <uri>file://media/materials/scripts/gazebo.material</uri>
          </script>
        </material>
      </visual>
      <visual name='base_footprint_fixed_joint_lump__front_sonar_link_visual_8'>
        <pose>1.8244 0 0.498 -4e-06 -0 4e-06</pose>
        <geometry>
          <box>
            <size>0.05 0.2 0.1</size>
          </box>
        </geometry>
        <material>
          <script>
            <name>Gazebo/Orange</name>
            <uri>file://media/materials/scripts/gazebo.material</uri>
          </script>
        </material>
      </visual>
      <visual name='base_footprint_fixed_joint_lump__front_radar_link_visual_9'>
        <pose>1.835 0 0.618 0 -0 0</pose>
        <geometry>
          <mesh>
            <scale>1 1 1</scale>
            <uri>model://gem_description/meshes/e4/front_radar_link.STL</uri>
          </mesh>
        </geometry>
        <material>
          <script>
            <name>Gazebo/White</name>
            <uri>file://media/materials/scripts/gazebo.material</uri>
          </script>
        </material>
      </visual>
      <visual name='base_footprint_fixed_joint_lump__front_right_corner_camera_link_visual_10'>
        <pose>0.5 -0.6535 2.018 -0 0.785 -0.785</pose>
        <geometry>
          <box>
            <size>0.02 0.02 0.01</size>
          </box>
        </geometry>
        <material>
          <script>
            <name>Gazebo/Green</name>
            <uri>file://media/materials/scripts/gazebo.material</uri>
          </script>
        </material>
      </visual>
      <visual name='base_footprint_fixed_joint_lump__gps_antenna_aux_link_visual_11'>
        <pose>-0.01144 -0.6525 1.968 0 -0 0</pose>
        <geometry>
          <mesh>
            <scale>1 1 1</scale>
            <uri>model://gem_description/meshes/e4/gps_antenna_aux_link.STL</uri>
          </mesh>
        </geometry>
        <material>
          <script>
            <name>Gazebo/White</name>
            <uri>file://media/materials/scripts/gazebo.material</uri>
          </script>
        </material>
      </visual>
      <visual name='base_footprint_fixed_joint_lump__gps_antenna_main_link_visual_12'>
        <pose>-0.01144 0.6525 1.968 0 -0 0</pose>
        <geometry>
          <mesh>
            <scale>1 1 1</scale>
            <uri>model://gem_description/meshes/e4/gps_antenna_main_link.STL</uri>
          </mesh>
        </geometry>
        <material>
          <script>
            <name>Gazebo/White</name>
            <uri>file://media/materials/scripts/gazebo.material</uri>
          </script>
        </material>
      </visual>
      <visual name='base_footprint_fixed_joint_lump__headlight_fl_link_visual_13'>
        <pose>1.1677 0.5 1.033 0 -0 0</pose>
        <geometry>
          <mesh>
            <scale>1 1 1</scale>
            <uri>model://gem_description/meshes/e4/headlight_fl_link.STL</uri>
          </mesh>
        </geometry>
        <material>
          <script>
            <name>Gazebo/White</name>
            <uri>file://media/materials/scripts/gazebo.material</uri>
          </script>
        </material>
      </visual>
      <visual name='base_footprint_fixed_joint_lump__headlight_fr_link_visual_14'>
        <pose>1.1677 -0.5 1.033 0 -0 0</pose>
        <geometry>
          <mesh>
            <scale>1 1 1</scale>
            <uri>model://gem_description/meshes/e4/headlight_fr_link.STL</uri>
          </mesh>
        </geometry>
        <material>
          <script>
            <name>Gazebo/White</name>
            <uri>file://media/materials/scripts/gazebo.material</uri>
          </script>
        </material>
      </visual>
      <visual name='base_footprint_fixed_joint_lump__i_logo_fl_link_visual_15'>
        <pose>0.3966 0.6695 0.6803 0 -0 0</pose>
        <geometry>
          <mesh>
            <scale>1 1 1</scale>
            <uri>model://gem_description/meshes/e4/i_logo_link.STL</uri>
          </mesh>
        </geometry>
        <material>
          <script>
            <name>Gazebo/Orange</name>
            <uri>file://media/materials/scripts/gazebo.material</uri>
          </script>
        </material>
      </visual>
      <visual name='base_footprint_fixed_joint_lump__i_logo_fr_link_visual_16'>
        <pose>0.3966 -0.68 0.6803 0 -0 0</pose>
        <geometry>
          <mesh>
            <scale>1 1 1</scale>
            <uri>model://gem_description/meshes/e4/i_logo_link.STL</uri>
          </mesh>
        </geometry>
        <material>
          <script>
            <name>Gazebo/Orange</name>
            <uri>file://media/materials/scripts/gazebo.material</uri>
          </script>
        </material>
      </visual>
      <visual name='base_footprint_fixed_joint_lump__i_logo_rl_link_visual_17'>
        <pose>-0.42344 0.6695 0.6803 0 -0 0</pose>
        <geometry>
          <mesh>
            <scale>1 1 1</scale>
            <uri>model://gem_description/meshes/e4/i_logo_link.STL</uri>
          </mesh>
        </geometry>
        <material>
          <script>
            <name>Gazebo/Orange</name>
            <uri>file://media/materials/scripts/gazebo.material</uri>
          </script>
        </material>
      </visual>
      <visual name='base_footprint_fixed_joint_lump__i_logo_rr_link_visual_18'>
        <pose>-0.42344 -0.68 0.6803 0 -0 0</pose>
        <geometry>
          <mesh>
            <scale>1 1 1</scale>
            <uri>model://gem_description/meshes/e4/i_logo_link.STL</uri>
          </mesh>
        </geometry>
        <material>
          <script>
            <name>Gazebo/Orange</name>
            <uri>file://media/materials/scripts/gazebo.material</uri>
          </script>
        </material>
      </visual>
      <visual name='base_footprint_fixed_joint_lump__imu_link_visual_19'>
        <pose>-0.004439 0 0.45094 0 -0 0</pose>
        <geometry>
          <mesh>
            <scale>1 1 1</scale>
            <uri>model://gem_description/meshes/e4/imu_link.STL</uri>
          </mesh>
        </geometry>
        <material>
          <script>
            <name>Gazebo/White</name>
            <uri>file://media/materials/scripts/gazebo.material</uri>
          </script>
        </material>
      </visual>
      <visual name='base_footprint_fixed_joint_lump__lightbar_link_visual_20'>
        <pose>-1.07655 0 1.2129 -1.9138 -0 1.5708</pose>
        <geometry>
          <mesh>
            <scale>1 1 1</scale>
            <uri>model://gem_description/meshes/e4/lightbar_link.STL</uri>
          </mesh>
        </geometry>
        <material>
          <script>
            <name>Gazebo/Red</name>
            <uri>file://media/materials/scripts/gazebo.material</uri>
          </script>
        </material>
      </visual>
      <visual name='base_footprint_fixed_joint_lump__rear_left_corner_camera_link_visual_21'>
        <pose>-1 0.6545 2.018 0 0.785 2.356</pose>
        <geometry>
          <box>
            <size>0.02 0.02 0.01</size>
          </box>
        </geometry>
        <material>
          <script>
            <name>Gazebo/Blue</name>
            <uri>file://media/materials/scripts/gazebo.material</uri>
          </script>
        </material>
      </visual>
      <visual name='base_footprint_fixed_joint_lump__rear_rack_link_visual_22'>
        <pose>-1.7372 0 0.168 1.5708 0 -1.5708</pose>
        <geometry>
          <mesh>
            <scale>1 1 1</scale>
            <uri>model://gem_description/meshes/e4/rear_rack_link.STL</uri>
          </mesh>
        </geometry>
        <material>
          <script>
            <name>Gazebo/Black</name>
            <uri>file://media/materials/scripts/gazebo.material</uri>
          </script>
        </material>
      </visual>
      <visual name='base_footprint_fixed_joint_lump__rear_sonar_link_visual_23'>
        <pose>-1.8022 0 0.548 -4e-06 -0 3.14159</pose>
        <geometry>
          <box>
            <size>0.05 0.2 0.1</size>
          </box>
        </geometry>
        <material>
          <script>
            <name>Gazebo/Orange</name>
            <uri>file://media/materials/scripts/gazebo.material</uri>
          </script>
        </material>
      </visual>
      <visual name='base_footprint_fixed_joint_lump__rear_right_corner_camera_link_visual_24'>
        <pose>-1 -0.6535 2.018 0 0.785 -2.356</pose>
        <geometry>
          <box>
            <size>0.02 0.02 0.01</size>
          </box>
        </geometry>
        <material>
          <script>
            <name>Gazebo/Yellow</name>
            <uri>file://media/materials/scripts/gazebo.material</uri>
          </script>
        </material>
      </visual>
      <visual name='base_footprint_fixed_joint_lump__rear_left_stop_light_link_visual_25'>
        <pose>-1.625 0.38 0.691 0 0 -3.14159</pose>
        <geometry>
          <mesh>
            <scale>1 1 1</scale>
            <uri>model://gem_description/meshes/e4/stoplight_rl_link.STL</uri>
          </mesh>
        </geometry>
        <material>
          <script>
            <name>Gazebo/White</name>
            <uri>file://media/materials/scripts/gazebo.material</uri>
          </script>
        </material>
      </visual>
      <visual name='base_footprint_fixed_joint_lump__rear_right_stop_light_link_visual_26'>
        <pose>-1.625 -0.38 0.691 0 0 -3.14159</pose>
        <geometry>
          <mesh>
            <scale>1 1 1</scale>
            <uri>model://gem_description/meshes/e4/stoplight_rr_link.STL</uri>
          </mesh>
        </geometry>
        <material>
          <script>
            <name>Gazebo/White</name>
            <uri>file://media/materials/scripts/gazebo.material</uri>
          </script>
        </material>
      </visual>
      <visual name='base_footprint_fixed_joint_lump__taillight_rl_link_visual_27'>
        <pose>-1.62 0.32 0.471 0 0 -3.14159</pose>
        <geometry>
          <mesh>
            <scale>1 1 1</scale>
            <uri>model://gem_description/meshes/e4/taillight_rl_link.STL</uri>
          </mesh>
        </geometry>
        <material>
          <script>
            <name>Gazebo/Red</name>
            <uri>file://media/materials/scripts/gazebo.material</uri>
          </script>
        </material>
      </visual>
      <visual name='base_footprint_fixed_joint_lump__taillight_rr_link_visual_28'>
        <pose>-1.62 -0.32 0.471 0 0 -3.14159</pose>
        <geometry>
          <mesh>
            <scale>1 1 1</scale>
            <uri>model://gem_description/meshes/e4/taillight_rr_link.STL</uri>
          </mesh>
        </geometry>
        <material>
          <script>
            <name>Gazebo/Red</name>
            <uri>file://media/materials/scripts/gazebo.material</uri>
          </script>
        </material>
      </visual>
      <visual name='base_footprint_fixed_joint_lump__top_lidar_link_visual_29'>
        <pose>-0.15144 0 2.348 0 -0 0</pose>
        <geometry>
          <mesh>
            <scale>1 1 1</scale>
            <uri>model://gem_description/meshes/e4/top_lidar_link.STL</uri>
          </mesh>
        </geometry>
        <material>
          <script>
            <name>Gazebo/White</name>
            <uri>file://media/materials/scripts/gazebo.material</uri>
          </script>
        </material>
      </visual>
      <visual name='base_footprint_fixed_joint_lump__top_rack_link_visual_30'>
        <pose>-0.17 0 1.928 1.5708 -0 0</pose>
        <geometry>
          <mesh>
            <scale>1 1 1</scale>
            <uri>model://gem_description/meshes/e4/top_rack_link.STL</uri>
          </mesh>
        </geometry>
        <material>
          <script>
            <name>Gazebo/Black</name>
            <uri>file://media/materials/scripts/gazebo.material</uri>
          </script>
        </material>
      </visual>
      <visual name='base_footprint_fixed_joint_lump__base_visual_visual_31'>
        <pose>-0.15 -2e-06 2.348 7e-06 0 -1.57089</pose>
        <geometry>
          <mesh>
            <scale>1 1 1</scale>
            <uri>model://gem_description/meshes/ouster/os1_64.dae</uri>
          </mesh>
        </geometry>
      </visual>
      <visual name='base_footprint_fixed_joint_lump__turnlight_fl_link_visual_32'>
        <pose>1.1731 0.345 1.033 0 -0 0</pose>
        <geometry>
          <mesh>
            <scale>1 1 1</scale>
            <uri>model://gem_description/meshes/e4/turnlight_fl_link.STL</uri>
          </mesh>
        </geometry>
        <material>
          <script>
            <name>Gazebo/Orange</name>
            <uri>file://media/materials/scripts/gazebo.material</uri>
          </script>
        </material>
      </visual>
      <visual name='base_footprint_fixed_joint_lump__turnlight_fr_link_visual_33'>
        <pose>1.1731 -0.345 1.033 0 -0 0</pose>
        <geometry>
          <mesh>
            <scale>1 1 1</scale>
            <uri>model://gem_description/meshes/e4/turnlight_fr_link.STL</uri>
          </mesh>
        </geometry>
        <material>
          <script>
            <name>Gazebo/Orange</name>
            <uri>file://media/materials/scripts/gazebo.material</uri>
          </script>
        </material>
      </visual>
      <sensor name='base_contact_sensor' type='contact'>
        <update_rate>50</update_rate>
        <always_on>1</always_on>
        <contact>
          <collision>base_footprint_fixed_joint_lump__base_link_collision</collision>
          <topic>__default_topic__</topic>
        </contact>
        <plugin name='base_bumper' filename='libgazebo_ros_bumper.so'>
          <ros>
            <namespace>/</namespace>
            <remapping>~/contacts:=contact_sensor</remapping>
          </ros>
          <frameName>base_link</frameName>
          <bumperTopicName>contact_sensor</bumperTopicName>
          <updateRate>50</updateRate>
          <contactTopicName>contact_sensor</contactTopicName>
          <verbose>1</verbose>
          <alwaysOn>1</alwaysOn>
        </plugin>
        <pose>0 0 0.268 0 -0 0</pose>
      </sensor>
      <sensor name='front_single_camera_sensor' type='camera'>
        <update_rate>23</update_rate>
        <camera>
          <horizontal_fov>1.5708</horizontal_fov>
          <image>
            <width>1152</width>
            <height>720</height>
            <format>R8G8B8</format>
          </image>
          <clip>
            <near>0.02</near>
            <far>300</far>
          </clip>
          <noise>
            <type>gaussian</type>
            <mean>0</mean>
            <stddev>0.007</stddev>
          </noise>
        </camera>
        <plugin name='front_single_camera_controller' filename='libgazebo_ros_camera.so'>
          <alwaysOn>1</alwaysOn>
          <updateRate>0.0</updateRate>
          <cameraName>oak/rgb</cameraName>
          <imageTopicName>image_raw</imageTopicName>
          <cameraInfoTopicName>camera_info</cameraInfoTopicName>
          <frameName>front_single_camera_link</frameName>
          <hackBaseline>0.07</hackBaseline>
          <distortionK1>0.0</distortionK1>
          <distortionK2>0.0</distortionK2>
          <distortionK3>0.0</distortionK3>
          <distortionT1>0.0</distortionT1>
          <distortionT2>0.0</distortionT2>
        </plugin>
        <pose>0.535 0 1.951 0 0.0008 0</pose>
      </sensor>
      <sensor name='front_left_corner_camera_sensor' type='camera'>
        <update_rate>48.3</update_rate>
        <camera>
          <horizontal_fov>1.5708</horizontal_fov>
          <image>
            <width>1920</width>
            <height>1200</height>
            <format>R8G8B8</format>
          </image>
          <clip>
            <near>0.02</near>
            <far>300</far>
          </clip>
          <noise>
            <type>gaussian</type>
            <mean>0</mean>
            <stddev>0.007</stddev>
          </noise>
        </camera>
        <plugin name='front_left_corner_camera_controller' filename='libgazebo_ros_camera.so'>
          <alwaysOn>1</alwaysOn>
          <updateRate>0.0</updateRate>
          <cameraName>camera_fl/arena_camera_node</cameraName>
          <imageTopicName>image_raw</imageTopicName>
          <cameraInfoTopicName>camera_info</cameraInfoTopicName>
          <frameName>front_left_corner_camera_link</frameName>
          <hackBaseline>0.07</hackBaseline>
          <distortionK1>0.0</distortionK1>
          <distortionK2>0.0</distortionK2>
          <distortionK3>0.0</distortionK3>
          <distortionT1>0.0</distortionT1>
          <distortionT2>0.0</distortionT2>
        </plugin>
        <pose>0.5 0.6545 2.018 0 0.785 0.785</pose>
      </sensor>
      <sensor name='front_rack_contact_sensor' type='contact'>
        <update_rate>50</update_rate>
        <always_on>1</always_on>
        <contact>
          <collision>base_footprint_fixed_joint_lump__front_rack_link_collision_6</collision>
          <topic>__default_topic__</topic>
        </contact>
        <plugin name='front_rack_bumper' filename='libgazebo_ros_bumper.so'>
          <ros>
            <namespace>/</namespace>
            <remapping>~/contacts:=contact_sensor</remapping>
          </ros>
          <frameName>front_rack_link</frameName>
          <bumperTopicName>contact_sensor</bumperTopicName>
          <updateRate>50</updateRate>
          <contactTopicName>contact_sensor</contactTopicName>
          <verbose>1</verbose>
          <alwaysOn>1</alwaysOn>
        </plugin>
        <pose>1.7594 0 0.118 1.5708 -0 1.5708</pose>
      </sensor>
      <sensor name='front_sonar_sensor' type='ray'>
        <always_on>1</always_on>
        <update_rate>20</update_rate>
        <visualize>0</visualize>
        <ray>
          <scan>
            <horizontal>
              <samples>2</samples>
              <resolution>1</resolution>
              <min_angle>-28</min_angle>
              <max_angle>28</max_angle>
            </horizontal>
            <vertical>
              <samples>2</samples>
              <resolution>1</resolution>
              <min_angle>-28</min_angle>
              <max_angle>28</max_angle>
            </vertical>
          </scan>
          <range>
            <min>0.3</min>
            <max>5</max>
            <resolution>0.01</resolution>
          </range>
        </ray>
        <plugin name='gazebo_ros_sonar_controller' filename='libhector_gazebo_ros_sonar.so'>
          <gaussianNoise>0.005</gaussianNoise>
          <topicName>/front_sonar_distance</topicName>
          <frameId>front_sonar_link</frameId>
        </plugin>
        <pose>1.8244 0 0.498 -4e-06 -0 4e-06</pose>
      </sensor>
      <sensor name='front_right_corner_camera_sensor' type='camera'>
        <update_rate>48.3</update_rate>
        <camera>
          <horizontal_fov>1.5708</horizontal_fov>
          <image>
            <width>1920</width>
            <height>1200</height>
            <format>R8G8B8</format>
          </image>
          <clip>
            <near>0.02</near>
            <far>300</far>
          </clip>
          <noise>
            <type>gaussian</type>
            <mean>0</mean>
            <stddev>0.007</stddev>
          </noise>
        </camera>
        <plugin name='front_right_corner_camera_controller' filename='libgazebo_ros_camera.so'>
          <alwaysOn>1</alwaysOn>
          <updateRate>0.0</updateRate>
          <cameraName>camera_fr/arena_camera_node</cameraName>
          <imageTopicName>image_raw</imageTopicName>
          <cameraInfoTopicName>camera_info</cameraInfoTopicName>
          <frameName>front_right_corner_camera_link</frameName>
          <hackBaseline>0.07</hackBaseline>
          <distortionK1>0.0</distortionK1>
          <distortionK2>0.0</distortionK2>
          <distortionK3>0.0</distortionK3>
          <distortionT1>0.0</distortionT1>
          <distortionT2>0.0</distortionT2>
        </plugin>
        <pose>0.5 -0.6535 2.018 0 0.785 -0.785</pose>
      </sensor>
      <sensor name='rear_left_corner_camera_sensor' type='camera'>
        <update_rate>48.3</update_rate>
        <camera>
          <horizontal_fov>1.5708</horizontal_fov>
          <image>
            <width>1920</width>
            <height>1200</height>
            <format>R8G8B8</format>
          </image>
          <clip>
            <near>0.02</near>
            <far>300</far>
          </clip>
          <noise>
            <type>gaussian</type>
            <mean>0</mean>
            <stddev>0.007</stddev>
          </noise>
        </camera>
        <plugin name='rear_left_corner_camera_controller' filename='libgazebo_ros_camera.so'>
          <alwaysOn>1</alwaysOn>
          <updateRate>0.0</updateRate>
          <cameraName>camera_rl/arena_camera_node</cameraName>
          <imageTopicName>image_raw</imageTopicName>
          <cameraInfoTopicName>camera_info</cameraInfoTopicName>
          <frameName>rear_left_corner_camera_link</frameName>
          <hackBaseline>0.07</hackBaseline>
          <distortionK1>0.0</distortionK1>
          <distortionK2>0.0</distortionK2>
          <distortionK3>0.0</distortionK3>
          <distortionT1>0.0</distortionT1>
          <distortionT2>0.0</distortionT2>
        </plugin>
        <pose>-1 0.6545 2.018 0 0.785 2.356</pose>
      </sensor>
      <sensor name='rear_rack_contact_sensor' type='contact'>
        <update_rate>50</update_rate>
        <always_on>1</always_on>
        <contact>
          <collision>base_footprint_fixed_joint_lump__rear_rack_link_collision_19</collision>
          <topic>__default_topic__</topic>
        </contact>
        <plugin name='rear_rack_bumper' filename='libgazebo_ros_bumper.so'>
          <ros>
            <namespace>/</namespace>
            <remapping>~/contacts:=contact_sensor</remapping>
          </ros>
          <frameName>rear_rack_link</frameName>
          <bumperTopicName>contact_sensor</bumperTopicName>
          <updateRate>50</updateRate>
          <contactTopicName>contact_sensor</contactTopicName>
          <verbose>1</verbose>
          <alwaysOn>1</alwaysOn>
        </plugin>
        <pose>-1.7372 0 0.168 1.5708 0 -1.5708</pose>
      </sensor>
      <sensor name='rear_sonar_sensor' type='ray'>
        <always_on>1</always_on>
        <update_rate>20</update_rate>
        <visualize>0</visualize>
        <ray>
          <scan>
            <horizontal>
              <samples>2</samples>
              <resolution>1</resolution>
              <min_angle>-28</min_angle>
              <max_angle>28</max_angle>
            </horizontal>
            <vertical>
              <samples>2</samples>
              <resolution>1</resolution>
              <min_angle>-28</min_angle>
              <max_angle>28</max_angle>
            </vertical>
          </scan>
          <range>
            <min>0.3</min>
            <max>5</max>
            <resolution>0.01</resolution>
          </range>
        </ray>
        <plugin name='gazebo_ros_sonar_controller' filename='libhector_gazebo_ros_sonar.so'>
          <gaussianNoise>0.005</gaussianNoise>
          <topicName>/rear_sonar_distance</topicName>
          <frameId>rear_sonar_link</frameId>
        </plugin>
        <pose>-1.8022 0 0.548 -4e-06 -0 3.14159</pose>
      </sensor>
      <sensor name='rear_right_corner_camera_sensor' type='camera'>
        <update_rate>48.3</update_rate>
        <camera>
          <horizontal_fov>1.5708</horizontal_fov>
          <image>
            <width>1920</width>
            <height>1200</height>
            <format>R8G8B8</format>
          </image>
          <clip>
            <near>0.02</near>
            <far>300</far>
          </clip>
          <noise>
            <type>gaussian</type>
            <mean>0</mean>
            <stddev>0.007</stddev>
          </noise>
        </camera>
        <plugin name='rear_right_corner_camera_controller' filename='libgazebo_ros_camera.so'>
          <alwaysOn>1</alwaysOn>
          <updateRate>0.0</updateRate>
          <cameraName>camera_rr/arena_camera_node</cameraName>
          <imageTopicName>image_raw</imageTopicName>
          <cameraInfoTopicName>camera_info</cameraInfoTopicName>
          <frameName>rear_right_corner_camera_link</frameName>
          <hackBaseline>0.07</hackBaseline>
          <distortionK1>0.0</distortionK1>
          <distortionK2>0.0</distortionK2>
          <distortionK3>0.0</distortionK3>
          <distortionT1>0.0</distortionT1>
          <distortionT2>0.0</distortionT2>
        </plugin>
        <pose>-1 -0.6535 2.018 0 0.785 -2.356</pose>
      </sensor>
      <sensor name='os_sensor-OS1-64' type='ray'>
        <visualize>0</visualize>
        <update_rate>10</update_rate>
        <ray>
          <scan>
            <horizontal>
              <samples>512</samples>
              <resolution>1</resolution>
              <min_angle>-3.14159</min_angle>
              <max_angle>3.14159</max_angle>
            </horizontal>
            <vertical>
              <samples>64</samples>
              <resolution>1</resolution>
              <min_angle>-0.26</min_angle>
              <max_angle>0.26</max_angle>
            </vertical>
          </scan>
          <range>
            <min>0.9</min>
            <max>75</max>
            <resolution>0.03</resolution>
          </range>
        </ray>
        <plugin name='gazebo_ros_laser_controller' filename='libgazebo_ros_ouster_laser.so'>
          <topicName>/ouster/points</topicName>
          <frameName>os_lidar</frameName>
          <min_range>0.9</min_range>
          <max_range>75.0</max_range>
          <gaussianNoise>0.008</gaussianNoise>
        </plugin>
        <pose>-0.15 -2e-06 2.348 0 7e-06 3.14159</pose>
      </sensor>
    </link>
    <joint name='left_steering_hinge_joint' type='revolute'>
      <pose relative_to='base_footprint'>1.2746 0.6545 0.295 0 -0 0</pose>
      <parent>base_footprint</parent>
      <child>left_steering_hinge_link</child>
      <axis>
        <xyz>0 0 1</xyz>
        <limit>
          <lower>-0.61</lower>
          <upper>0.61</upper>
          <effort>100</effort>
          <velocity>0.5</velocity>
        </limit>
        <dynamics>
          <spring_reference>0</spring_reference>
          <spring_stiffness>0</spring_stiffness>
        </dynamics>
      </axis>
    </joint>
    <link name='left_steering_hinge_link'>
      <pose relative_to='left_steering_hinge_joint'>0 0 0 0 -0 0</pose>
      <inertial>
        <pose>0 0 0 0 -0 0</pose>
        <mass>1</mass>
        <inertia>
          <ixx>0.004</ixx>
          <ixy>0</ixy>
          <ixz>0</ixz>
          <iyy>0.004</iyy>
          <iyz>0</iyz>
          <izz>0.004</izz>
        </inertia>
      </inertial>
    </link>
    <joint name='front_left_wheel_joint' type='revolute'>
      <pose relative_to='left_steering_hinge_link'>0 0 0 0 -0 0</pose>
      <parent>left_steering_hinge_link</parent>
      <child>front_left_wheel_link</child>
      <axis>
        <xyz>0 1 0</xyz>
        <limit>
          <effort>1000</effort>
          <velocity>100</velocity>
          <lower>-1e+16</lower>
          <upper>1e+16</upper>
        </limit>
        <dynamics>
          <spring_reference>0</spring_reference>
          <spring_stiffness>0</spring_stiffness>
        </dynamics>
      </axis>
    </joint>
    <link name='front_left_wheel_link'>
      <pose relative_to='front_left_wheel_joint'>0 0 0 0 -0 0</pose>
      <inertial>
        <pose>0 0 0 0 -0 0</pose>
        <mass>11</mass>
        <inertia>
          <ixx>0.586312</ixx>
          <ixy>0</ixy>
          <ixz>0</ixz>
          <iyy>0.335529</iyy>
          <iyz>0</iyz>
          <izz>0.335529</izz>
        </inertia>
      </inertial>
      <collision name='front_left_wheel_link_fixed_joint_lump__front_left_wheel_collision_collision'>
        <pose>0 0 0 0 -0 0</pose>
        <geometry>
          <sphere>
            <radius>0.295</radius>
          </sphere>
        </geometry>
      </collision>
      <visual name='front_left_wheel_link_visual'>
        <pose>0 0 0 0 -0 0</pose>
        <geometry>
          <mesh>
            <scale>1 1 1</scale>
            <uri>model://gem_description/meshes/e4/wheel_link_fl.STL</uri>
          </mesh>
        </geometry>
        <material>
          <script>
            <name>Gazebo/Black</name>
            <uri>file://media/materials/scripts/gazebo.material</uri>
          </script>
        </material>
      </visual>
    </link>
    <joint name='rear_left_wheel_joint' type='revolute'>
      <pose relative_to='base_footprint'>-1.2904 0.6545 0.295 0 -0 0</pose>
      <parent>base_footprint</parent>
      <child>rear_left_wheel_link</child>
      <axis>
        <xyz>0 1 0</xyz>
        <limit>
          <effort>1000</effort>
          <velocity>100</velocity>
          <lower>-1e+16</lower>
          <upper>1e+16</upper>
        </limit>
        <dynamics>
          <spring_reference>0</spring_reference>
          <spring_stiffness>0</spring_stiffness>
        </dynamics>
      </axis>
    </joint>
    <link name='rear_left_wheel_link'>
      <pose relative_to='rear_left_wheel_joint'>0 0 0 0 -0 0</pose>
      <inertial>
        <pose>0 0 0 0 -0 0</pose>
        <mass>11</mass>
        <inertia>
          <ixx>0.586312</ixx>
          <ixy>0</ixy>
          <ixz>0</ixz>
          <iyy>0.335529</iyy>
          <iyz>0</iyz>
          <izz>0.335529</izz>
        </inertia>
      </inertial>
      <collision name='rear_left_wheel_link_fixed_joint_lump__rear_left_wheel_collision_collision'>
        <pose>0 0 0 0 -0 0</pose>
        <geometry>
          <sphere>
            <radius>0.295</radius>
          </sphere>
        </geometry>
      </collision>
      <visual name='rear_left_wheel_link_visual'>
        <pose>0 0 0 0 -0 0</pose>
        <geometry>
          <mesh>
            <scale>1 1 1</scale>
            <uri>model://gem_description/meshes/e4/wheel_link_rl.STL</uri>
          </mesh>
        </geometry>
        <material>
          <script>
            <name>Gazebo/Black</name>
            <uri>file://media/materials/scripts/gazebo.material</uri>
          </script>
        </material>
      </visual>
    </link>
    <joint name='rear_right_wheel_joint' type='revolute'>
      <pose relative_to='base_footprint'>-1.2904 -0.6535 0.295 0 -0 0</pose>
      <parent>base_footprint</parent>
      <child>rear_right_wheel_link</child>
      <axis>
        <xyz>0 1 0</xyz>
        <limit>
          <effort>1000</effort>
          <velocity>100</velocity>
          <lower>-1e+16</lower>
          <upper>1e+16</upper>
        </limit>
        <dynamics>
          <spring_reference>0</spring_reference>
          <spring_stiffness>0</spring_stiffness>
        </dynamics>
      </axis>
    </joint>
    <link name='rear_right_wheel_link'>
      <pose relative_to='rear_right_wheel_joint'>0 0 0 0 -0 0</pose>
      <inertial>
        <pose>0 0 0 0 -0 0</pose>
        <mass>11</mass>
        <inertia>
          <ixx>0.586312</ixx>
          <ixy>0</ixy>
          <ixz>0</ixz>
          <iyy>0.335529</iyy>
          <iyz>0</iyz>
          <izz>0.335529</izz>
        </inertia>
      </inertial>
      <collision name='rear_right_wheel_link_fixed_joint_lump__rear_right_wheel_collision_collision'>
        <pose>0 0 0 0 -0 0</pose>
        <geometry>
          <sphere>
            <radius>0.295</radius>
          </sphere>
        </geometry>
      </collision>
      <visual name='rear_right_wheel_link_visual'>
        <pose>0 0 0 0 -0 0</pose>
        <geometry>
          <mesh>
            <scale>1 1 1</scale>
            <uri>model://gem_description/meshes/e4/wheel_link_rr.STL</uri>
          </mesh>
        </geometry>
        <material>
          <script>
            <name>Gazebo/Black</name>
            <uri>file://media/materials/scripts/gazebo.material</uri>
          </script>
        </material>
      </visual>
    </link>
    <joint name='right_steering_hinge_joint' type='revolute'>
      <pose relative_to='base_footprint'>1.2746 -0.6535 0.295 0 -0 0</pose>
      <parent>base_footprint</parent>
      <child>right_steering_hinge_link</child>
      <axis>
        <xyz>0 0 1</xyz>
        <limit>
          <lower>-0.61</lower>
          <upper>0.61</upper>
          <effort>100</effort>
          <velocity>0.5</velocity>
        </limit>
        <dynamics>
          <spring_reference>0</spring_reference>
          <spring_stiffness>0</spring_stiffness>
        </dynamics>
      </axis>
    </joint>
    <link name='right_steering_hinge_link'>
      <pose relative_to='right_steering_hinge_joint'>0 0 0 0 -0 0</pose>
      <inertial>
        <pose>0 0 0 0 -0 0</pose>
        <mass>1</mass>
        <inertia>
          <ixx>0.004</ixx>
          <ixy>0</ixy>
          <ixz>0</ixz>
          <iyy>0.004</iyy>
          <iyz>0</iyz>
          <izz>0.004</izz>
        </inertia>
      </inertial>
    </link>
    <joint name='front_right_wheel_joint' type='revolute'>
      <pose relative_to='right_steering_hinge_link'>0 0 0 0 -0 0</pose>
      <parent>right_steering_hinge_link</parent>
      <child>front_right_wheel_link</child>
      <axis>
        <xyz>0 1 0</xyz>
        <limit>
          <effort>1000</effort>
          <velocity>100</velocity>
          <lower>-1e+16</lower>
          <upper>1e+16</upper>
        </limit>
        <dynamics>
          <spring_reference>0</spring_reference>
          <spring_stiffness>0</spring_stiffness>
        </dynamics>
      </axis>
    </joint>
    <link name='front_right_wheel_link'>
      <pose relative_to='front_right_wheel_joint'>0 0 0 0 -0 0</pose>
      <inertial>
        <pose>0 0 0 0 -0 0</pose>
        <mass>11</mass>
        <inertia>
          <ixx>0.586312</ixx>
          <ixy>0</ixy>
          <ixz>0</ixz>
          <iyy>0.335529</iyy>
          <iyz>0</iyz>
          <izz>0.335529</izz>
        </inertia>
      </inertial>
      <collision name='front_right_wheel_link_fixed_joint_lump__front_right_wheel_collision_collision'>
        <pose>0 0 0 0 -0 0</pose>
        <geometry>
          <sphere>
            <radius>0.295</radius>
          </sphere>
        </geometry>
      </collision>
      <visual name='front_right_wheel_link_visual'>
        <pose>0 0 0 0 -0 0</pose>
        <geometry>
          <mesh>
            <scale>1 1 1</scale>
            <uri>model://gem_description/meshes/e4/wheel_link_fr.STL</uri>
          </mesh>
        </geometry>
        <material>
          <script>
            <name>Gazebo/Black</name>
            <uri>file://media/materials/scripts/gazebo.material</uri>
          </script>
        </material>
      </visual>
    </link>
    <plugin name='gazebo_ros_control' filename='libgazebo_ros_control.so'>
      <legacyModeNS>1</legacyModeNS>
      <robotSimType>gazebo_ros_control/DefaultRobotHWSim</robotSimType>
    </plugin>
    <plugin name='planar_move' filename='libgazebo_ros_planar_move.so'>
      <ros>
        <namespace>/</namespace>
      </ros>
      <update_rate>50</update_rate>
      <publish_rate>50</publish_rate>
      <publish_odom>1</publish_odom>
      <publish_odom_tf>1</publish_odom_tf>
      <odometry_frame>odom</odometry_frame>
      <robot_base_frame>base_footprint</robot_base_frame>
      <covariance_x>0.0001</covariance_x>
      <covariance_y>0.0001</covariance_y>
      <covariance_yaw>0.01</covariance_yaw>
    </plugin>
    <plugin name='imu_plugin' filename='libgazebo_ros_imu.so'>
      <alwaysOn>1</alwaysOn>
      <topicName>imu</topicName>
      <serviceName>imu_service</serviceName>
      <gaussianNoise>0.0</gaussianNoise>
      <updateRate>50.0</updateRate>
      <bodyName>base_footprint</bodyName>
      <frameName>base_footprint</frameName>
      <xyzOffset>0.245999 0.246 -0.636</xyzOffset>
      <rpyOffset>0 -0 0.000486846</rpyOffset>
    </plugin>
    <plugin name='gazebo_ros_gps' filename='libhector_gazebo_ros_gps.so'>
      <updateRate>20.0</updateRate>
      <frameId>GPS_link</frameId>
      <topicName>/gps/fix</topicName>
      <velocityTopicName>/gps/fix_velocity</velocityTopicName>
      <useWorldSphericalCoordinates>1</useWorldSphericalCoordinates>
      <offset>0 0 0</offset>
      <drift>0.001 0.001 0.001</drift>
      <gaussianNoise>0.05 0.05 0.05</gaussianNoise>
      <velocityDrift>0.001 0.001 0.001</velocityDrift>
      <velocityGaussianNoise>0.5 0.5 0.5</velocityGaussianNoise>
      <bodyName>base_footprint</bodyName>
      <xyzOffset>0.246 0 -0.318</xyzOffset>
      <rpyOffset>0 -0 0</rpyOffset>
    </plugin>
    <static>0</static>
    <plugin name='imu_controller' filename='libhector_gazebo_ros_imu.so'>
      <robotNamespace>/</robotNamespace>
      <updateRate>100.0</updateRate>
      <topicName>/ouster/imu</topicName>
      <accelDrift>0.005 0.005 0.005</accelDrift>
      <accelGaussianNoise>0.005 0.005 0.005</accelGaussianNoise>
      <rateDrift>0.005 0.005 0.005</rateDrift>
      <rateGaussianNoise>0.005 0.005 0.005</rateGaussianNoise>
      <headingDrift>0.005</headingDrift>
      <headingGaussianNoise>0.005</headingGaussianNoise>
      <bodyName>base_footprint</bodyName>
      <xyzOffset>0.156253 0.0117767 -1.50036</xyzOffset>
      <rpyOffset>-0.0269371 -0.000956983 1.27751e-09</rpyOffset>
    </plugin>
  </model>
</sdf>
